Workbook

Sheet Company Planning
D7: Company Annual Targets
C8: 1 | D8: MARKET SHARE (US si GR)
C9: 2 | D9: CASH (CCC)
C10: 3 | D10: EBIT
C11: 4 | D11: NET REVENUE (CAN)
C12: 5 | D12: B2C ACTIVE UNIQUE CUSTOMERS
C13: 6 | D13: SHARE GOOD ROUTINE (value & %)
C14: 7 | D14: SHARE OF A PLAYERS
D15: Company Annual priorities (big rocks) | K15: WHO | L15: KPI
C16: 1 | D16: Improve portfolio mix | K16: Tudor & Mada | L16: share vs immunity
C17: 2 | D17: JBPs with national chains | K17: Lucia / Paul | L17: net revenue
C18: 3 | D18: Consolidate RTM - launch Pediatric division, incentive, SIS, accelerator program, telesales, vizibilitate Secom in farmacii | K18: Lucia / Paul | L18: net revenue
C19: 4 | D19: Deploy digital sales channels | K19: Radu | L19: 10% of net online sales
C20: 5 | D20: Launch the new Retail concept | K20: Radu | L20: 1st of May
C21: 6 | D21: Improve execution of commercial calender - day by day, launch the new US campaign - de la scump la premium, commercial routines, launch brand etic corporate campaign | K21: Tudor & Mada | L21: 95% OTIF
C22: 7 | D22: Launch Good Routine Kids | K22: Mada | L22: Net revenue
C23: 8 | D23: Launch Good Routine Wellness Foods | K23: Andrei | L23: Portfolio
C24: 9 | D24: AI in business - discovering tools that can increase market share | K24: Johnny
C25: 10 | D25: Pilot in Modern Trade | K25: Paul
C26: 11 | D26: Digitalize/Automize top 5 processes - Forecast & Purchasing, Order to Cash, Reporting | K26: Johnny
C27: 12 | D27: Cost reduction program | K27: Adina
C28: 13 | D28: Talent Management program | K28: Andreia
C29: 14 | D29: Sustenabilitate | K29: Alina / Lucia | L29: 80% din Obiective
C30: 15 | D30: Logistics Excellence - TBD Idei | K30: George
C31: 16 | D31: Customer Centricity -> Share idei per Stakeholder (%) | K31: Alexandra / Adina | L31: 100 Idei Implementate
D33: Company Q1 targets
C34: 1 | D34: MARKET SHARE
C35: 2 | D35: CASH
C36: 3 | D36: EBIT
C37: 4 | D37: NET REVENUE
C38: 5 | D38: FINALIZE NEW RETAIL CONCEPT
C39: 6 | D39: MARKET SHARE GOOD ROUTINE vs SHARE GOOD ROUTINE (value & %)
C40: 7 | D40: FINALIZE TALENT MANAGEMENT CONCEPT & EVALUATION
D41: Company Q1 priorities (big rocks) | K41: WHO | L41: KPI
C42: 1 | K42: Department 1
C43: 2
C44: 3
C45: 4
C46: 5
C47: 6
...

Sheet Department 1 - Q Planning
C1: DEPARTMENT 1 [NAME] QUARTERLY PLAN
D4: Department 1
C5: Q1 targets
C6: 1 | D6: Talent Management process deployed
C7: 2 | D7: Merit increase - keep in the budget
C8: 3 | D8: Recruit L&D
C9: 4 | D9: Organize National Conference
C10: 5 | D10: Finish Performance management process for 2024
C11: Q1 priorities | E11: WHO | F11: KPI
C12: 1 | D12: Organize National Conference | E12: Doris | F12: In budget
C13: 2 | D13: Deploy Talent Management process & organize session for Managers of managers | E13: Andreia | F13: End of March
C14: 3 | D14: Analyse, propose & do Merit increase - 15 mar | E14: Doris | F14: In time & in budget
C15: 4 | D15: Finish Performance management process for 2024 | E15: Doris | F15: 20-Feb
C16: 5 | D16: Recruit L&D | E16: Dina | F16: End of Jan
D19: Team member 1 (Name) | H19: Team member 2(Name) | L19: Team member 3 (Name) | P19: Team member 4 (Name) | T19: Team member 5 (Name) | X19: Team member 6 (Name)
C20: Q1 priorities | E20: KPI | G20: Q1 priorities | I20: KPI | K20: Q1 priorities | M20: KPI | O20: Q1 priorities | Q20: KPI | S20: Q1 priorities | U20: KPI | W20: Q1 priorities | Y20: KPI
C21: 1 | D21: Organize National Conference | E21: in the budget | G21: 1 | H21: Organize National Conference | I21: in the budget | K21: 1 | L21: Priority 1 | M21: % | O21: 1 | P21: Priority 1 | Q21: % | S21: 1 | T21: Priority 1 | U21: % | W21: 1 | X21: Priority 1 | Y21: %
C22: 2 | D22: Analyse, propose & do Merit increase - 15 mar | E22: End of March | G22: 2 | H22: Training Telesales Team | I22: Over 90% test score | K22: 2 | L22: Priority 2 | M22: % | O22: 2 | P22: Priority 2 | Q22: % | S22: 2 | T22: Priority 2 | U22: % | W22: 2 | X22: Priority 2 | Y22: %
C23: 3 | D23: Finish Performance management process for 2024 & Start & update Performance Management for 2025 | E23: End of Feb | G23: 3 | H23: Recruit L&D | I23: End of Jan | K23: 3 | L23: Priority 3 | M23: date | O23: 3 | P23: Priority 3 | Q23: date | S23: 3 | T23: Priority 3 | U23: # | W23: 3 | X23: Priority 3 | Y23: #
C24: 4 | D24: Priority 4 | E24: # | G24: 4 | H24: Priority 4 | I24: # | K24: 4 | L24: Priority 4 | M24: # | O24: 4 | P24: Priority 4 | Q24: # | S24: 4 | T24: Priority 4 | U24: # | W24: 4 | X24: Priority 4 | Y24: #
C25: 5 | D25: Priority 5 | E25: % | G25: 5 | H25: Priority 5 | I25: % | K25: 5 | L25: Priority 5 | M25: % | O25: 5 | P25: Priority 5 | Q25: % | S25: 5 | T25: Priority 5 | U25: % | W25: 5 | X25: Priority 5 | Y25: %

Sheet Department 1 - Week Performance
C1: DEPARTMENT 1 [NAME] WEEKLY AND DAILY PERFORMANCE
C4: ='Department 1 - Q Planning'!D19 -> Team member 1 (Name) | K4: =C4 -> Team member 1 (Name) | S4: =K4 -> Team member 1 (Name)
C5: Link to A | D5: # | E5: Q PRIORITIES | I5: KPI | K5: Link to A | L5: # | M5: Q PRIORITIES | Q5: KPI | S5: Link to A | T5: # | U5: Q PRIORITIES | Y5: KPI
D6: 1 | E6: ='Department 1 - Q Planning'!D21 -> Organize National Conference | I6: ='Department 1 - Q Planning'!E21 -> in the budget | L6: 1 | M6: =E6 -> Organize National Conference | Q6: =I6 -> in the budget | T6: 1 | U6: =M6 -> Organize National Conference | Y6: =Q6 -> in the budget
D7: 2 | E7: ='Department 1 - Q Planning'!D22 -> Analyse, propose & do Merit increase - 15 mar | I7: ='Department 1 - Q Planning'!E22 -> End of March | L7: 2 | M7: =E7 -> Analyse, propose & do Merit increase - 15 mar | Q7: =I7 -> End of March | T7: 2 | U7: =M7 -> Analyse, propose & do Merit increase - 15 mar | Y7: =Q7 -> End of March
D8: 3 | E8: ='Department 1 - Q Planning'!D23 -> Finish Performance management process for 2024 & Start & update Performance Management for 2025 | I8: ='Department 1 - Q Planning'!E23 -> End of Feb | L8: 3 | M8: =E8 -> Finish Performance management process for 2024 & Start & update Performance Management for 2025 | Q8: =I8 -> End of Feb | T8: 3 | U8: =M8 -> Finish Performance management process for 2024 & Start & update Performance Management for 2025 | Y8: =Q8 -> End of Feb
D9: 4 | E9: ='Department 1 - Q Planning'!D24 -> Priority 4 | I9: ='Department 1 - Q Planning'!E24 -> # | L9: 4 | M9: =E9 -> Priority 4 | Q9: =I9 -> # | T9: 4 | U9: =M9 -> Priority 4 | Y9: =Q9 -> #
D10: 5 | E10: ='Department 1 - Q Planning'!D25 -> Priority 5 | I10: ='Department 1 - Q Planning'!E25 -> % | L10: 5 | M10: =E10 -> Priority 5 | Q10: =I10 -> % | T10: 5 | U10: =M10 -> Priority 5 | Y10: =Q10 -> %
E11: WEEKLY PRIORITIES | M11: WEEKLY PRIORITIES | U11: WEEKLY PRIORITIES
C12: Link to Q | D12: # | E12: 47 | F12: DAY | G12: Completed? | H12: Reason if not completed | I12: WEEKLY LEARNING | K12: Link to Q | L12: # | M12: =E12+1 -> 48 | N12: DAY | O12: Completed? | P12: Reason if not completed | Q12: WEEKLY LEARNING | S12: Link to Q | T12: # | U12: =M12+1 -> 49 | V12: DAY | W12: Completed? | X12: Reason if not completed | Y12: WEEKLY LEARNING
D13: 1 | E13: Agree the presentation deck for Conference | F13: 1 | L13: 1 | T13: 1
D14: 2 | E14: List the Nominees for Awards | F14: 2 | L14: 2 | T14: 2
D15: 3 | E15: Confirm the participation list | F15: 3 | L15: 3 | T15: 3
D16: 4 | E16: Follow up with the Agency for the Conference activities | F16: 4 | L16: 4 | T16: 4
D17: 5 | E17: Create the Merit increase template and share the proposals with the BU directors | F17: 5 | L17: 5 | T17: 5
D18: 6 | L18: 6 | T18: 6
D19: Link to W | E19: DAILY PRIORITIES | F19: TIME | G19: Completed? | H19: Reason if not completed | I19: DAILY LEARNING | L19: Link to W | M19: DAILY PRIORITIES | N19: TIME | O19: Completed? | P19: Reason if not completed | Q19: DAILY LEARNING | T19: Link to W | U19: DAILY PRIORITIES | V19: TIME | W19: Completed? | X19: Reason if not completed | Y19: DAILY LEARNING
C20: M | E20: Share with Board members the contect and the template design for Conference | K20: M | S20: M
C23: T | K23: T | S23: T
C26: W | K26: W | S26: W
C29: T | K29: T | S29: T
C32: F | K32: F | S32: F
C37: ='Department 1 - Q Planning'!H19 -> Team member 2(Name) | K37: =C37 -> Team member 2(Name) | S37: =K37 -> Team member 2(Name)
C38: Link to A | D38: # | E38: Q PRIORITIES | I38: KPI | K38: Link to A | L38: # | M38: Q PRIORITIES | Q38: KPI | S38: Link to A | T38: # | U38: Q PRIORITIES | Y38: KPI
D39: 1 | E39: ='Department 1 - Q Planning'!H21 -> Organize National Conference | I39: ='Department 1 - Q Planning'!I21 -> in the budget | L39: 1 | M39: =E39 -> Organize National Conference | Q39: =I39 -> in the budget | T39: 1 | U39: =M39 -> Organize National Conference | Y39: =Q39 -> in the budget
D40: 2 | E40: ='Department 1 - Q Planning'!H22 -> Training Telesales Team | I40: ='Department 1 - Q Planning'!I22 -> Over 90% test score | L40: 2 | M40: =E40 -> Training Telesales Team | Q40: =I40 -> Over 90% test score | T40: 2 | U40: =M40 -> Training Telesales Team | Y40: =Q40 -> Over 90% test score
D41: 3 | E41: ='Department 1 - Q Planning'!H23 -> Recruit L&D | I41: ='Department 1 - Q Planning'!I23 -> End of Jan | L41: 3 | M41: =E41 -> Recruit L&D | Q41: =I41 -> End of Jan | T41: 3 | U41: =M41 -> Recruit L&D | Y41: =Q41 -> End of Jan
D42: 4 | E42: ='Department 1 - Q Planning'!H24 -> Priority 4 | I42: ='Department 1 - Q Planning'!I24 -> # | L42: 4 | M42: =E42 -> Priority 4 | Q42: =I42 -> # | T42: 4 | U42: =M42 -> Priority 4 | Y42: =Q42 -> #
D43: 5 | E43: ='Department 1 - Q Planning'!H25 -> Priority 5 | I43: ='Department 1 - Q Planning'!I25 -> % | L43: 5 | M43: =E43 -> Priority 5 | Q43: =I43 -> % | T43: 5 | U43: =M43 -> Priority 5 | Y43: =Q43 -> %
E44: WEEKLY PRIORITIES | M44: WEEKLY PRIORITIES | U44: WEEKLY PRIORITIES
C45: Link to Q | D45: # | E45: 47 | F45: DAY | G45: Completed? | H45: Reason if not completed | I45: WEEKLY LEARNING | K45: Link to Q | L45: # | M45: =E45+1 -> 48 | N45: DAY | O45: Completed? | P45: Reason if not completed | Q45: WEEKLY LEARNING | S45: Link to Q | T45: # | U45: =M45+1 -> 49 | V45: DAY | W45: Completed? | X45: Reason if not completed | Y45: WEEKLY LEARNING
D46: 1 | E46: Screening 50 cv's for L&D | L46: 1 | T46: 1
D47: 2 | E47: Select the best 10 and gave the short interview, propose min. 3. If not, screen again. | L47: 2 | T47: 2
D48: 3 | L48: 3 | T48: 3
D49: 4 | L49: 4 | T49: 4
D50: 5 | L50: 5 | T50: 5
D51: 6 | L51: 6 | T51: 6
D52: Link to W | E52: DAILY PRIORITIES | F52: TIME | G52: Completed? | H52: Reason if not completed | I52: DAILY LEARNING | L52: Link to W | M52: DAILY PRIORITIES | N52: TIME | O52: Completed? | P52: Reason if not completed | Q52: DAILY LEARNING | T52: Link to W | U52: DAILY PRIORITIES | V52: TIME | W52: Completed? | X52: Reason if not completed | Y52: DAILY LEARNING
C53: M | K53: M | S53: M
C56: T | K56: T | S56: T
...

Sheet Dropdowns
B1: COMPLETION | D1: Reason if not completed
B2: Yes | D2: Bad scheduling
B3: No | D3: Not enough time
D4: Lack of capabilities
D5: Lack of resources
D6: No discipline
D7: Emergencies
